<?xml version="1.0"?>

<robot name="six_bot" xmlns:xacro="http://www.ros.org/wiki/xacro">
  <!--xacro:include filename="$(find ghettobot)/urdf/ghettobot.gazebo"/-->
  <xacro:include filename="$(find iai_kinect2_description)/urdf/kinect2.urdf.xacro"/>
  


  <link name="robot_footprint"></link>

  <joint type="fixed" name="robot_footprint_joint">
    <origin xyz="0 0 0.094" rpy="0 0 0"/>
    <parent link="robot_footprint"/>
    <child link="chassis"/>
  </joint>





  <link name="chassis">
    <pose>0 0 0.094 0 0 0</pose>

    <inertial>
      <mass value="5.0"/>
      <origin xyz="0 0 0" rpy="0 0 0"/>
      <inertia
          ixx="0.1" ixy="0" ixz="0"
          iyy="0.1" iyz="0"
          izz="0.1"
      />
    </inertial>

    <collision name="collision">
      <origin xyz="0 0 0" rpy="0 0 0"/> 
      <geometry>
        <mesh filename="package://ghettobot/meshes/dollybase.stl"/>    
        <!--cylinder length="0.01835" radius="0.190"/--> 
      </geometry>
    </collision>

    <visual name="chassis_visual">
      <origin xyz="0 0 0" rpy="0 0 0"/>
      <geometry>
        <mesh filename="package://ghettobot/meshes/dollybase.stl"/>
      </geometry>
    </visual>
  </link>






  <link name="right_wheel1">
    <collision name="right_wheel1_collision">
      <origin xyz="0 0 0" rpy="1.570796327 0 0"/> 
      <geometry>
        <cylinder length="0.05714286" radius="0.06561899"/> 
      </geometry>
    </collision>

    <inertial>
      <mass value="1.0"/>
      <origin xyz="0 0 0" rpy="0 0 0"/>
      <inertia
          ixx="0.1" ixy="0" ixz="0"
          iyy="0.1" iyz="0"
          izz="0.1" />
    </inertial>

    <visual name="right_wheel1_visual">
      <origin xyz="0 0 0" rpy="0 0 1.570796327"/>
      <geometry>
        <mesh filename="package://ghettobot/meshes/wheel.stl"/>
      </geometry>
    </visual>
  
  </link>

  <joint type="continuous" name="right_wheel1_hinge">
    <origin xyz="-0.10498 -0.22955 -0.025" rpy="0 0 0"/> <!--0.03238-->
    <child link="right_wheel1"/> 
    <parent link="chassis"/>
    <axis xyz="0 1 0" rpy="0 0 0"/>
    <limit effort="10000" velocity="1000"/>
    <dynamics damping="1.0" friction="1.0"/>

  </joint>







  <link name="left_wheel1">
    <inertial>
      <mass value="1.0"/>
      <origin xyz="0 0 0" rpy="0 0 0"/>
      <inertia
          ixx="0.1" ixy="0" ixz="0"
          iyy="0.1" iyz="0"
          izz="0.1" />
    </inertial>

    <collision name="left_wheel1_collision">
      <origin xyz="0 0 0" rpy="1.570796327 0 0"/> 
      <geometry>
        <cylinder length="0.05714286" radius="0.06561899"/> 
      </geometry>
    </collision>

    <visual name="left_wheel1_visual">
      <origin xyz="0 0 0" rpy="0 0 -1.570796327"/>
      <geometry>
        <mesh filename="package://ghettobot/meshes/wheel.stl"/>
      </geometry>
    </visual>
  
  </link>

  <joint type="continuous" name="left_wheel1_hinge">
    <origin xyz="-0.10498 0.22955 -0.025" rpy="0 0 0"/> <!--0.03238-->
    <child link="left_wheel1"/> 
    <parent link="chassis"/>
    <axis xyz="0 1 0" rpy="0 0 0"/>
    <limit effort="10000" velocity="1000"/>
    <dynamics damping="1.0" friction="1.0"/>

  </joint>

  <link name="caster">   
    <collision name="caster_collision">
      <origin xyz="0 0 0" rpy="0 0 0"/>
      <geometry>
        <sphere radius="0.049"/>
      </geometry>
      <surface>
        <friction>
          <ode>
            <mu>0.00</mu>
            <mu2>0.00</mu2>
          </ode>
        </friction>
      </surface>
    </collision>

    <visual name="caster_visual">
      <origin xyz="0 0 0" rpy="0 0 0"/>
      <geometry>
        <sphere radius="0.049"/>
      </geometry>
    </visual>
  </link>

  <joint type="fixed" name="caster_joint">
    <origin xyz="0.13566 0 -0.049" rpy="0 0 0"/>
    <child link="caster"/> 
    <parent link="chassis"/>
  </joint>

   





<link name="shelf_support_left_bottom">
    <collision name="shelf_support_left_bottom_collision">
      <origin xyz="0 0 0" rpy="0 0 0"/>
        <geometry>
	  <mesh filename="package://ghettobot/meshes/shelfsupport.stl"/>
          <!--box size="0.05 0.05 0.09"/-->
          <!-- box size="0.1 0.1 0.1"/-->
        </geometry>
    </collision>

    <inertial>
      <mass value="0.05"/>
      <origin xyz="0 0 0" rpy="0 0 0"/>
      <inertia
          ixx="1e-6" ixy="0" ixz="0"
          iyy="1e-6" iyz="0"
          izz="1e-6" />
    </inertial>

    <visual name="shelf_support_left_bottom_visual">
      <origin xyz="0 0 0" rpy="0 0 0"/>
      <geometry>
        <mesh filename="package://ghettobot/meshes/shelfsupport.stl"/>
      </geometry>
    </visual>
  </link>

  <joint type="fixed" name="shelf_support_left_bottom_joint">
    <origin xyz="0 0.15336 0.01835" rpy="0 0 3.141592654"/>
    <child link="shelf_support_left_bottom"/> 
    <parent link="chassis"/>
  </joint>





<link name="shelf_support_right_bottom">
    <collision name="shelf_support_right_bottom_collision">
      <origin xyz="0 0 0" rpy="0 0 0"/>
        <geometry>
	  <mesh filename="package://ghettobot/meshes/shelfsupport.stl"/>
          <!--box size="0.05 0.05 0.09"/-->
          <!-- box size="0.1 0.1 0.1"/-->
        </geometry>
    </collision>

    <inertial>
      <mass value="0.05"/>
      <origin xyz="0 0 0" rpy="0 0 0"/>
      <inertia
          ixx="1e-6" ixy="0" ixz="0"
          iyy="1e-6" iyz="0"
          izz="1e-6" />
    </inertial>

    <visual name="shelf_support_right_bottom_visual">
      <origin xyz="0 0 0" rpy="0 0 0"/>
      <geometry>
        <mesh filename="package://ghettobot/meshes/shelfsupport.stl"/>
      </geometry>
    </visual>
  </link>

  <joint type="fixed" name="shelf_support_right_bottom_joint">
    <origin xyz="0 -0.15336 0.01835" rpy="0 0 3.141592654"/>
    <child link="shelf_support_right_bottom"/> 
    <parent link="chassis"/>
  </joint>




<link name="shelf1">
    <collision name="shelf1_collision">
      <origin xyz="0 0 0" rpy="0 0 0"/>
        <geometry>
	  <mesh filename="package://ghettobot/meshes/shelf1.stl"/>
          <!--box size="0.05 0.05 0.09"/-->
          <!-- box size="0.1 0.1 0.1"/-->
        </geometry>
    </collision>

    <inertial>
      <mass value="0.05"/>
      <origin xyz="0 0 0" rpy="0 0 0"/>
      <inertia
          ixx="1e-6" ixy="0" ixz="0"
          iyy="1e-6" iyz="0"
          izz="1e-6" />
    </inertial>

    <visual name="shelf1_visual">
      <origin xyz="0 0 0" rpy="0 0 0"/>
      <geometry>
        <mesh filename="package://ghettobot/meshes/shelf1.stl"/>
      </geometry>
    </visual>
  </link>

  <joint type="fixed" name="shelf1_joint">
    <origin xyz="0.02354 -0.152316 0.1" rpy="0 0 0"/>
    <child link="shelf1"/> 
    <parent link="shelf_support_right_bottom"/>
  </joint>

<link name="kinect_spacer_centre">
    <collision name="kinect_spacer_centre_collision">
      <origin xyz="0 0 0" rpy="0 0 0"/>
        <geometry>
	  <mesh filename="package://ghettobot/meshes/shelf1.stl"/>
          <!--box size="0.05 0.05 0.09"/-->
          <!-- box size="0.1 0.1 0.1"/-->
        </geometry>
    </collision>

    <inertial>
      <mass value="0.05"/>
      <origin xyz="0 0 0" rpy="0 0 0"/>
      <inertia
          ixx="1e-6" ixy="0" ixz="0"
          iyy="1e-6" iyz="0"
          izz="1e-6" />
    </inertial>

    <visual name="kinect_spacer_centre_visual">
      <origin xyz="0 0 0" rpy="0 0 0"/>
      <geometry>
        <mesh filename="package://ghettobot/meshes/kinect_spacer_centre.stl"/>
      </geometry>
    </visual>
  </link>

  <joint type="fixed" name="kinect_spacer_centre_joint">
    <origin xyz="-0.108 0 0" rpy="0 0 0"/>
    <child link="kinect_spacer_centre"/> 
    <parent link="shelf1"/>
  </joint>


        <kinect2_xacro parent="shelf1" prefix="shelf1">
                <!-- From CAD -->
		<!--origin xyz="-0.02 0.10 0.02" rpy="-1.570795 0 1.570795" /-->
                <!-- From Halcon calibration on 20160902 -->
		<origin xyz="-0.0825  0.09494 0.059" rpy="0 -0.244346 3.14159265359"/> <!--"0.06438 -0.098 0.17986154"--> <!--0.08441383--><!--origin xyz="-0.0815  0.09494 0.059" rpy="0 -0.116937 3.14159265359"/-->
        </kinect2_xacro>




<link name="shelf_support_right_upper">
    <collision name="shelf_support_right_upper_collision">
      <origin xyz="0 0 0" rpy="0 0 0"/>
        <geometry>
	  <mesh filename="package://ghettobot/meshes/shelfsupport.stl"/>
          <!--box size="0.05 0.05 0.09"/-->
          <!-- box size="0.1 0.1 0.1"/-->
        </geometry>
    </collision>

    <inertial>
      <mass value="0.05"/>
      <origin xyz="0 0 0" rpy="0 0 0"/>
      <inertia
          ixx="1e-6" ixy="0" ixz="0"
          iyy="1e-6" iyz="0"
          izz="1e-6" />
    </inertial>

    <visual name="shelf_support_right_upper_visual">
      <origin xyz="0 0 0" rpy="0 0 0"/>
      <geometry>
        <mesh filename="package://ghettobot/meshes/shelfsupport.stl"/>
      </geometry>
    </visual>
  </link>

  <joint type="fixed" name="shelf_support_right_upper_joint">
    <origin xyz="0.002 0.136 0.0174" rpy="0 0 0"/>
    <child link="shelf_support_right_upper"/> 
    <parent link="shelf1"/>
  </joint>




<link name="shelf2">
    <collision name="shelf2_collision">
      <origin xyz="0 0 0" rpy="0 0 0"/>
        <geometry>
	  <mesh filename="package://ghettobot/meshes/shelf2.stl"/>
          <!--box size="0.05 0.05 0.09"/-->
          <!-- box size="0.1 0.1 0.1"/-->
        </geometry>
    </collision>

    <inertial>
      <mass value="0.05"/>
      <origin xyz="0 0 0" rpy="0 0 0"/>
      <inertia
          ixx="1e-6" ixy="0" ixz="0"
          iyy="1e-6" iyz="0"
          izz="1e-6" />
    </inertial>

    <visual name="shelf2_visual">
      <origin xyz="0 0 0" rpy="0 0 0"/>
      <geometry>
        <mesh filename="package://ghettobot/meshes/shelf2.stl"/>
      </geometry>
    </visual>
  </link>

  <joint type="fixed" name="shelf2_joint">
    <origin xyz="0.02554 -0.136 0.1" rpy="0 0 0"/>
    <child link="shelf2"/> 
    <parent link="shelf_support_right_upper"/>
  </joint>




  <!--link name="camera">
    <collision name="camera_collision">
      <origin xyz="0 0 0" rpy="0 0 0"/>
        <geometry>      
          <box size="0.045 0.045 0.045"/>
        </geometry>
    </collision>

    <inertial>
      <mass value="0.1"/>
      <origin xyz="0 0 0" rpy="0 0 0"/>
      <inertia
          ixx="1e-6" ixy="0" ixz="0"
          iyy="1e-6" iyz="0"
          izz="1e-6" />
    </inertial>

    <visual name="camera_visual">
      <origin xyz="0 0 0" rpy="0 0 0"/>
      <geometry>
        <box size="0.045 0.045 0.045"/>
      </geometry>
    </visual>
  
  </link>

  <joint name="camera_joint" type="fixed">
    <origin xyz="0.15 0 0.045" rpy="0 0 0"/>
    <child link="camera"/> 
    <parent link="chassis"/>
  </joint-->






<link name="lidar">
    <collision name="lidar_collision">
      <origin xyz="0 0 0" rpy="0 0 0"/>
        <geometry>
          <box size="0.1 0.1 0.1"/>
          <!-- box size="0.1 0.1 0.1"/-->
        </geometry>
    </collision>

    <inertial>
      <mass value="0.1"/>
      <origin xyz="0 0 0" rpy="0 0 0"/>
      <inertia
          ixx="1e-6" ixy="0" ixz="0"
          iyy="1e-6" iyz="0"
          izz="1e-6" />
    </inertial>

    <visual name="lidar_visual">
      <origin xyz="0 0 0" rpy="0 0 0"/>
      <geometry>
        <mesh filename="package://ghettobot/meshes/lidar.stl"/>
      </geometry>
    </visual>
  
  </link>

  <joint type="fixed" name="lidar_joint">
  <origin xyz="-0.05123366 0 0.0789" rpy="0 0 0"/>
    <!--origin xyz="-0.05123366 0 0.09975" rpy="0 0 3.141592654"/-->
    <child link="lidar"/> 
    <parent link="shelf2"/>
  </joint>

</robot>
